2022-03-01 18:26:34,250 INFO    MainThread:2868 [internal.py:wandb_internal():89] W&B internal server running at pid: 2868, started at: 2022-03-01 18:26:34.250839
2022-03-01 18:26:34,252 INFO    WriterThread:2868 [datastore.py:open_for_write():77] open: E:\Python\Mahdis Projects\assignment-41\wandb\run-20220301_182630-6liotvaa\run-6liotvaa.wandb
2022-03-01 18:26:34,253 DEBUG   HandlerThread:2868 [handler.py:handle_request():131] handle_request: check_version
2022-03-01 18:26:34,256 DEBUG   SenderThread:2868 [sender.py:send():235] send: header
2022-03-01 18:26:34,256 DEBUG   SenderThread:2868 [sender.py:send_request():249] send_request: check_version
2022-03-01 18:26:35,315 DEBUG   SenderThread:2868 [sender.py:send():235] send: run
2022-03-01 18:26:36,010 ERROR   SenderThread:2868 [internal_api.py:execute():143] 403 response executing GraphQL.
2022-03-01 18:26:36,010 ERROR   SenderThread:2868 [internal_api.py:execute():144] 
<html><head>
<meta http-equiv="content-type" content="text/html;charset=utf-8">
<title>403 Forbidden</title>
</head>
<body text=#000000 bgcolor=#ffffff>
<h1>Error: Forbidden</h1>
<h2>Your client does not have permission to get URL <code>/graphql</code> from this server.</h2>
<h2></h2>
</body></html>

2022-03-01 18:26:36,326 INFO    WriterThread:2868 [datastore.py:close():281] close: E:\Python\Mahdis Projects\assignment-41\wandb\run-20220301_182630-6liotvaa\run-6liotvaa.wandb
2022-03-01 18:26:36,326 INFO    HandlerThread:2868 [handler.py:finish():739] shutting down handler
2022-03-01 18:26:36,326 ERROR   MainThread:2868 [internal.py:wandb_internal():164] Thread SenderThread:
Traceback (most recent call last):
  File "c:\users\user\appdata\local\programs\python\python39\lib\site-packages\wandb\sdk\lib\retry.py", line 102, in __call__
    result = self._call_fn(*args, **kwargs)
  File "c:\users\user\appdata\local\programs\python\python39\lib\site-packages\wandb\sdk\internal\internal_api.py", line 146, in execute
    six.reraise(*sys.exc_info())
  File "c:\users\user\appdata\local\programs\python\python39\lib\site-packages\six.py", line 719, in reraise
    raise value
  File "c:\users\user\appdata\local\programs\python\python39\lib\site-packages\wandb\sdk\internal\internal_api.py", line 140, in execute
    return self.client.execute(*args, **kwargs)
  File "c:\users\user\appdata\local\programs\python\python39\lib\site-packages\wandb\vendor\gql-0.2.0\gql\client.py", line 52, in execute
    result = self._get_result(document, *args, **kwargs)
  File "c:\users\user\appdata\local\programs\python\python39\lib\site-packages\wandb\vendor\gql-0.2.0\gql\client.py", line 60, in _get_result
    return self.transport.execute(document, *args, **kwargs)
  File "c:\users\user\appdata\local\programs\python\python39\lib\site-packages\wandb\vendor\gql-0.2.0\gql\transport\requests.py", line 39, in execute
    request.raise_for_status()
  File "c:\users\user\appdata\local\programs\python\python39\lib\site-packages\requests\models.py", line 953, in raise_for_status
    raise HTTPError(http_error_msg, response=self)
requests.exceptions.HTTPError: 403 Client Error: Forbidden for url: https://api.wandb.ai/graphql

During handling of the above exception, another exception occurred:

Traceback (most recent call last):
  File "c:\users\user\appdata\local\programs\python\python39\lib\site-packages\wandb\apis\normalize.py", line 24, in wrapper
    return func(*args, **kwargs)
  File "c:\users\user\appdata\local\programs\python\python39\lib\site-packages\wandb\sdk\internal\internal_api.py", line 1296, in upsert_run
    response = self.gql(mutation, variable_values=variable_values, **kwargs)
  File "c:\users\user\appdata\local\programs\python\python39\lib\site-packages\wandb\sdk\lib\retry.py", line 118, in __call__
    if not check_retry_fn(e):
  File "c:\users\user\appdata\local\programs\python\python39\lib\site-packages\wandb\util.py", line 821, in no_retry_auth
    raise CommError("Permission denied, ask the project owner to grant you access")
wandb.errors.CommError: Permission denied, ask the project owner to grant you access

During handling of the above exception, another exception occurred:

Traceback (most recent call last):
  File "c:\users\user\appdata\local\programs\python\python39\lib\site-packages\wandb\sdk\internal\internal_util.py", line 54, in run
    self._run()
  File "c:\users\user\appdata\local\programs\python\python39\lib\site-packages\wandb\sdk\internal\internal_util.py", line 105, in _run
    self._process(record)
  File "c:\users\user\appdata\local\programs\python\python39\lib\site-packages\wandb\sdk\internal\internal.py", line 305, in _process
    self._sm.send(record)
  File "c:\users\user\appdata\local\programs\python\python39\lib\site-packages\wandb\sdk\internal\sender.py", line 237, in send
    send_handler(record)
  File "c:\users\user\appdata\local\programs\python\python39\lib\site-packages\wandb\sdk\internal\sender.py", line 692, in send_run
    self._init_run(run, config_value_dict)
  File "c:\users\user\appdata\local\programs\python\python39\lib\site-packages\wandb\sdk\internal\sender.py", line 716, in _init_run
    server_run, inserted = self._api.upsert_run(
  File "c:\users\user\appdata\local\programs\python\python39\lib\site-packages\wandb\apis\normalize.py", line 62, in wrapper
    six.reraise(CommError, CommError(message, err), sys.exc_info()[2])
  File "c:\users\user\appdata\local\programs\python\python39\lib\site-packages\six.py", line 718, in reraise
    raise value.with_traceback(tb)
  File "c:\users\user\appdata\local\programs\python\python39\lib\site-packages\wandb\apis\normalize.py", line 24, in wrapper
    return func(*args, **kwargs)
  File "c:\users\user\appdata\local\programs\python\python39\lib\site-packages\wandb\sdk\internal\internal_api.py", line 1296, in upsert_run
    response = self.gql(mutation, variable_values=variable_values, **kwargs)
  File "c:\users\user\appdata\local\programs\python\python39\lib\site-packages\wandb\sdk\lib\retry.py", line 118, in __call__
    if not check_retry_fn(e):
  File "c:\users\user\appdata\local\programs\python\python39\lib\site-packages\wandb\util.py", line 821, in no_retry_auth
    raise CommError("Permission denied, ask the project owner to grant you access")
wandb.errors.CommError: Permission denied, ask the project owner to grant you access
2022-03-01 18:26:38,405 INFO    MainThread:2868 [internal.py:handle_exit():79] Internal process exited
