2022-03-01 18:08:06,238 INFO    MainThread:11860 [internal.py:wandb_internal():89] W&B internal server running at pid: 11860, started at: 2022-03-01 18:08:06.143463
2022-03-01 18:08:06,242 INFO    WriterThread:11860 [datastore.py:open_for_write():77] open: E:\Python\Mahdis Projects\assignment-41\wandb\run-20220301_180804-27ndd8rk\run-27ndd8rk.wandb
2022-03-01 18:08:06,243 DEBUG   HandlerThread:11860 [handler.py:handle_request():131] handle_request: check_version
2022-03-01 18:08:06,259 DEBUG   SenderThread:11860 [sender.py:send():235] send: header
2022-03-01 18:08:06,259 DEBUG   SenderThread:11860 [sender.py:send_request():249] send_request: check_version
2022-03-01 18:08:11,276 DEBUG   SenderThread:11860 [sender.py:send():235] send: run
2022-03-01 18:08:17,872 ERROR   SenderThread:11860 [retry.py:__call__():126] Retry attempt failed:
Traceback (most recent call last):
  File "c:\users\user\appdata\local\programs\python\python39\lib\site-packages\urllib3\connection.py", line 174, in _new_conn
    conn = connection.create_connection(
  File "c:\users\user\appdata\local\programs\python\python39\lib\site-packages\urllib3\util\connection.py", line 73, in create_connection
    for res in socket.getaddrinfo(host, port, family, socket.SOCK_STREAM):
  File "c:\users\user\appdata\local\programs\python\python39\lib\socket.py", line 954, in getaddrinfo
    for res in _socket.getaddrinfo(host, port, family, type, proto, flags):
socket.gaierror: [Errno 11002] getaddrinfo failed

During handling of the above exception, another exception occurred:

Traceback (most recent call last):
  File "c:\users\user\appdata\local\programs\python\python39\lib\site-packages\urllib3\connectionpool.py", line 699, in urlopen
    httplib_response = self._make_request(
  File "c:\users\user\appdata\local\programs\python\python39\lib\site-packages\urllib3\connectionpool.py", line 382, in _make_request
    self._validate_conn(conn)
  File "c:\users\user\appdata\local\programs\python\python39\lib\site-packages\urllib3\connectionpool.py", line 1010, in _validate_conn
    conn.connect()
  File "c:\users\user\appdata\local\programs\python\python39\lib\site-packages\urllib3\connection.py", line 358, in connect
    conn = self._new_conn()
  File "c:\users\user\appdata\local\programs\python\python39\lib\site-packages\urllib3\connection.py", line 186, in _new_conn
    raise NewConnectionError(
urllib3.exceptions.NewConnectionError: <urllib3.connection.HTTPSConnection object at 0x000001CBBE134B80>: Failed to establish a new connection: [Errno 11002] getaddrinfo failed

During handling of the above exception, another exception occurred:

Traceback (most recent call last):
  File "c:\users\user\appdata\local\programs\python\python39\lib\site-packages\requests\adapters.py", line 439, in send
    resp = conn.urlopen(
  File "c:\users\user\appdata\local\programs\python\python39\lib\site-packages\urllib3\connectionpool.py", line 755, in urlopen
    retries = retries.increment(
  File "c:\users\user\appdata\local\programs\python\python39\lib\site-packages\urllib3\util\retry.py", line 574, in increment
    raise MaxRetryError(_pool, url, error or ResponseError(cause))
urllib3.exceptions.MaxRetryError: HTTPSConnectionPool(host='api.wandb.ai', port=443): Max retries exceeded with url: /graphql (Caused by NewConnectionError('<urllib3.connection.HTTPSConnection object at 0x000001CBBE134B80>: Failed to establish a new connection: [Errno 11002] getaddrinfo failed'))

During handling of the above exception, another exception occurred:

Traceback (most recent call last):
  File "c:\users\user\appdata\local\programs\python\python39\lib\site-packages\wandb\sdk\lib\retry.py", line 102, in __call__
    result = self._call_fn(*args, **kwargs)
  File "c:\users\user\appdata\local\programs\python\python39\lib\site-packages\wandb\sdk\internal\internal_api.py", line 140, in execute
    return self.client.execute(*args, **kwargs)
  File "c:\users\user\appdata\local\programs\python\python39\lib\site-packages\wandb\vendor\gql-0.2.0\gql\client.py", line 52, in execute
    result = self._get_result(document, *args, **kwargs)
  File "c:\users\user\appdata\local\programs\python\python39\lib\site-packages\wandb\vendor\gql-0.2.0\gql\client.py", line 60, in _get_result
    return self.transport.execute(document, *args, **kwargs)
  File "c:\users\user\appdata\local\programs\python\python39\lib\site-packages\wandb\vendor\gql-0.2.0\gql\transport\requests.py", line 38, in execute
    request = requests.post(self.url, **post_args)
  File "c:\users\user\appdata\local\programs\python\python39\lib\site-packages\requests\api.py", line 117, in post
    return request('post', url, data=data, json=json, **kwargs)
  File "c:\users\user\appdata\local\programs\python\python39\lib\site-packages\requests\api.py", line 61, in request
    return session.request(method=method, url=url, **kwargs)
  File "c:\users\user\appdata\local\programs\python\python39\lib\site-packages\requests\sessions.py", line 542, in request
    resp = self.send(prep, **send_kwargs)
  File "c:\users\user\appdata\local\programs\python\python39\lib\site-packages\requests\sessions.py", line 655, in send
    r = adapter.send(request, **kwargs)
  File "c:\users\user\appdata\local\programs\python\python39\lib\site-packages\requests\adapters.py", line 516, in send
    raise ConnectionError(e, request=request)
requests.exceptions.ConnectionError: HTTPSConnectionPool(host='api.wandb.ai', port=443): Max retries exceeded with url: /graphql (Caused by NewConnectionError('<urllib3.connection.HTTPSConnection object at 0x000001CBBE134B80>: Failed to establish a new connection: [Errno 11002] getaddrinfo failed'))
2022-03-01 18:08:39,577 DEBUG   HandlerThread:11860 [handler.py:handle_request():131] handle_request: shutdown
2022-03-01 18:08:39,578 INFO    HandlerThread:11860 [handler.py:finish():739] shutting down handler
2022-03-01 18:08:39,779 INFO    WriterThread:11860 [datastore.py:close():281] close: E:\Python\Mahdis Projects\assignment-41\wandb\run-20220301_180804-27ndd8rk\run-27ndd8rk.wandb
2022-03-01 18:08:44,956 ERROR   SenderThread:11860 [internal_api.py:execute():143] 403 response executing GraphQL.
2022-03-01 18:08:44,956 ERROR   SenderThread:11860 [internal_api.py:execute():144] 
<html><head>
<meta http-equiv="content-type" content="text/html;charset=utf-8">
<title>403 Forbidden</title>
</head>
<body text=#000000 bgcolor=#ffffff>
<h1>Error: Forbidden</h1>
<h2>Your client does not have permission to get URL <code>/graphql</code> from this server.</h2>
<h2></h2>
</body></html>

2022-03-01 18:08:44,956 ERROR   MainThread:11860 [internal.py:wandb_internal():164] Thread SenderThread:
Traceback (most recent call last):
  File "c:\users\user\appdata\local\programs\python\python39\lib\site-packages\wandb\sdk\lib\retry.py", line 102, in __call__
    result = self._call_fn(*args, **kwargs)
  File "c:\users\user\appdata\local\programs\python\python39\lib\site-packages\wandb\sdk\internal\internal_api.py", line 146, in execute
    six.reraise(*sys.exc_info())
  File "c:\users\user\appdata\local\programs\python\python39\lib\site-packages\six.py", line 719, in reraise
    raise value
  File "c:\users\user\appdata\local\programs\python\python39\lib\site-packages\wandb\sdk\internal\internal_api.py", line 140, in execute
    return self.client.execute(*args, **kwargs)
  File "c:\users\user\appdata\local\programs\python\python39\lib\site-packages\wandb\vendor\gql-0.2.0\gql\client.py", line 52, in execute
    result = self._get_result(document, *args, **kwargs)
  File "c:\users\user\appdata\local\programs\python\python39\lib\site-packages\wandb\vendor\gql-0.2.0\gql\client.py", line 60, in _get_result
    return self.transport.execute(document, *args, **kwargs)
  File "c:\users\user\appdata\local\programs\python\python39\lib\site-packages\wandb\vendor\gql-0.2.0\gql\transport\requests.py", line 39, in execute
    request.raise_for_status()
  File "c:\users\user\appdata\local\programs\python\python39\lib\site-packages\requests\models.py", line 953, in raise_for_status
    raise HTTPError(http_error_msg, response=self)
requests.exceptions.HTTPError: 403 Client Error: Forbidden for url: https://api.wandb.ai/graphql

During handling of the above exception, another exception occurred:

Traceback (most recent call last):
  File "c:\users\user\appdata\local\programs\python\python39\lib\site-packages\wandb\apis\normalize.py", line 24, in wrapper
    return func(*args, **kwargs)
  File "c:\users\user\appdata\local\programs\python\python39\lib\site-packages\wandb\sdk\internal\internal_api.py", line 1296, in upsert_run
    response = self.gql(mutation, variable_values=variable_values, **kwargs)
  File "c:\users\user\appdata\local\programs\python\python39\lib\site-packages\wandb\sdk\lib\retry.py", line 118, in __call__
    if not check_retry_fn(e):
  File "c:\users\user\appdata\local\programs\python\python39\lib\site-packages\wandb\util.py", line 821, in no_retry_auth
    raise CommError("Permission denied, ask the project owner to grant you access")
wandb.errors.CommError: Permission denied, ask the project owner to grant you access

During handling of the above exception, another exception occurred:

Traceback (most recent call last):
  File "c:\users\user\appdata\local\programs\python\python39\lib\site-packages\wandb\sdk\internal\internal_util.py", line 54, in run
    self._run()
  File "c:\users\user\appdata\local\programs\python\python39\lib\site-packages\wandb\sdk\internal\internal_util.py", line 105, in _run
    self._process(record)
  File "c:\users\user\appdata\local\programs\python\python39\lib\site-packages\wandb\sdk\internal\internal.py", line 305, in _process
    self._sm.send(record)
  File "c:\users\user\appdata\local\programs\python\python39\lib\site-packages\wandb\sdk\internal\sender.py", line 237, in send
    send_handler(record)
  File "c:\users\user\appdata\local\programs\python\python39\lib\site-packages\wandb\sdk\internal\sender.py", line 692, in send_run
    self._init_run(run, config_value_dict)
  File "c:\users\user\appdata\local\programs\python\python39\lib\site-packages\wandb\sdk\internal\sender.py", line 716, in _init_run
    server_run, inserted = self._api.upsert_run(
  File "c:\users\user\appdata\local\programs\python\python39\lib\site-packages\wandb\apis\normalize.py", line 62, in wrapper
    six.reraise(CommError, CommError(message, err), sys.exc_info()[2])
  File "c:\users\user\appdata\local\programs\python\python39\lib\site-packages\six.py", line 718, in reraise
    raise value.with_traceback(tb)
  File "c:\users\user\appdata\local\programs\python\python39\lib\site-packages\wandb\apis\normalize.py", line 24, in wrapper
    return func(*args, **kwargs)
  File "c:\users\user\appdata\local\programs\python\python39\lib\site-packages\wandb\sdk\internal\internal_api.py", line 1296, in upsert_run
    response = self.gql(mutation, variable_values=variable_values, **kwargs)
  File "c:\users\user\appdata\local\programs\python\python39\lib\site-packages\wandb\sdk\lib\retry.py", line 118, in __call__
    if not check_retry_fn(e):
  File "c:\users\user\appdata\local\programs\python\python39\lib\site-packages\wandb\util.py", line 821, in no_retry_auth
    raise CommError("Permission denied, ask the project owner to grant you access")
wandb.errors.CommError: Permission denied, ask the project owner to grant you access
2022-03-01 18:08:47,083 INFO    MainThread:11860 [internal.py:handle_exit():79] Internal process exited
